from anaconda_auth.client import *  # noqa: F403
from anaconda_cloud_auth import warn  # noqa: F401

# The following import addresses a bug in Navigator, which imported from the wrong module by mistake
from anaconda_cloud_auth.config import AnacondaCloudConfig  # noqa: F401

warn()
