from anaconda_cloud_auth.exceptions import *  # noqa: F403
